Workbook

Sheet SE_Kompetenzen_SE4OWL
B2: Kompetenzen | C2: Definition | D2: Repräsentiert INCOSE Kompetenzen | F2: Beschriebung Reifegrad | G2: Stufe 0 | H2: Stufe 1 | I2: Stufe 2 | J2: Stufe 3 | K2: Stufe 4
G3: Nicht bewusst vorhanden | H3: Individuell/Ad Hoc | I3: Fragmentiert | J3: Etabliert | K3: Systematische Förderung
A4: Kern Kompetenzen | B4: Systemisches Denken | C4: Die Kompetenz fundamentale Konzepte des Systemdenkens im Systems Engineering anzuwenden und die Rolle des eigenen Systems in seinem Gesamtkontext zu verstehen. | D4: Systemisches Denken, Capability Engineering | F4: Wichtiger Bestandteil der SE-Philosophie ist die Verbreitung und Verwendung des Systemdenkens. Darunter wird eine Denkweise verstanden, die es ermöglicht, komplexe Systeme besser zu verstehen und zu gestalten und somit ein ganzheitliches Systemverständnis zu erzeugen [Gei19; HWF+19; WRF+15]. | G4: Ansätze, Methoden und Verhaltensmuster des Systemdenkens sind im Unternehmen nicht verbreitet. Ein einheitliches Systemverständnis fehlt. Einzelne Prinzipien des Systemdenkens werden, wenn überhaupt nur unbewusst genutzt. | H4: Einzelne Personen nutzen Ansätze und Methoden des Systemdenkens für ihre individuellen Tätigkeiten, wie z.B. der Erhöhung des individuellen Systemverständnisses. Grundlegende Tätigkeiten, wie die Systemdefinition werden ausgeführt. Eine ganzheitliche Systembetrachtung findet nicht statt. | I4: Einzelne Organisationseinheiten nutzen Ansätze und Methoden des Systemdenkens für einzelne Projekte. Innerhalb dieser Projekte werden Systeme schon ganzheitlich betrachtet, so dass innerhalb des Projektteams ein gutes Systemverständnis besteht. | J4: Das Systemdenken wird unternehmensweit gelebt. Wesentliche Begriffe der Systembeschreibung sind bei allen beteiligten Personen einheitlich definiert und bekannt. Ansätze und Methoden dieser Denkweise werden automatisch genutzt, um ein System ganzheitlich zu betrachten und das Systemverständnis zu erhöhen. | K4: Zusätzlich zu der unternehmensweiten Verbreitung der mit dem Systemdenken und dem ganzheitlichen Systemverständnis verbundenen Ansätze und Methoden werden bestehende Strukturen kontinuierlich optimiert und neue Ansätze und Methoden systematisch integriert.
B5: Systemmodellierung und -analyse | C5: Die Kompetenz exakte Daten und Informationen mit HIlfe von domäne-übergreifenden Modellen bereitzustellen, um das technische Verständnis und das Treffen von Entscheidungen zu unterstützen. | D5: Systemmodellierung und -analyse | F5: Modellbasiertes Arbeiten dient dem Zweck, die Aktivitäten zur Beschreibung der Systemspezifikation von Beginn der konzeptionellen Architekturgestaltung über die Entwicklung bis hin zu späten Phasen des System-Lebenszyklus zu unterstützen und durch eine formalisierte Anwendung der einzelnen Aktivitäten Entscheidungsprozesse und Analysen kostengünstig und zeitgenau verfügbar zu machen. | G5: Die Systemspezifikation wird nicht disziplinübergreifend modellbasiert beschrieben. | H5: Einzelne Aspekte der Systemspezifikation werden durch disziplinübergreifende Modelle beschrieben. Das modellbasierte Arbeiten erfolgt nicht auf Basis einer expliziten MBSE-Methode. | I5: Einzelne Aspekte der Systemspezifikation werden durch modellbasiertes Arbeiten unterstützt. Es werden einzelne Schritte einer MBSE-Methode angewandt. | J5: Die Beschreibung der disziplinübergreifenden Systemspezifikation erfolgt durchgehend auf Basis einer MBSE-Methode. Durch Richtlinien und Vorgaben ist definiert, in welcher Form und Ausprägung die modellbasierte Systemspezifikation das System-of-Interest beschreibt. | K5: Die MBSE-Methode ist unternehmens-spezifisch angepasst. Die Leistungsfähigkeit der Methode wird kontinuierlich optimiert.
B6: Berücksichtigung von Systemlebenszyklusphasen | C6: Die Kompetenz während der Realisierung eines Systems die anderen Lebenszyklen außer der Betriebsphase in den Systemanforderungen, -architekturen und -designs zu berücksichtigen. | D6: Lebenszyklen, Geschäfts- und Unternehmensintegration
B7: Agiles Denken / Kunden-Nutzenorientierung | C7: Die Kompetenz die agilen Werte / den Kundennutzen in den Mittelpunkt der Entwicklung zu stellen.
A8: Fachkompetenzen | B8: Anforderungsmanagement | C8: Die Kompetenz Bedürfnisse und Erwartungen der Stakeholder zu analysieren und daraus Anforderungen für ein System festzulegen. | D8: Definition von Anforderungen, Geschäfts- und Unternehmensintegration | F8: Ermittlung von Anforderungen sowie deren Dokumentation und Erstellung entsprechender Anforderungsdokumente (als strukturierte Menge von Anforderungen). | G8: Es gibt keinen systematischen und strukturierten Ansatz, um Anforderungen im Rahmen des SE zu ermitteln und zu dokumentieren. Die Dokumentation von Anforderungen erfolgt nicht oder unstrukturiert. | H8: Zur Dokumentation von Anforderungen stehen Dokumentenvorlagen bereit. Vereinzelte RE-Prozess- und Methodenbausteine sind vorhanden und werden genutzt. | I8: Ein RE-Prozess von der Identifikation bis zur Abstimmung von Anforderungen existiert, kann projektspezifisch angepasst werden und wird größtenteils angewandt. Anforderungen werden unter Nutzung des Systemdenkens strukturiert und mittels formeller Vorgaben dokumentiert. Definierte Qualitätskriterien für Anforderungen und Anforderungsdokumente sind vorhanden. | J8: Der RE-Prozess ist unternehmensweit etabliert. Es existieren unternehmensweite Vorgaben zur Strukturierung von Anforderungen mittels Systemdenkens. Es existiert ein Sicherheitsprozess und geeignete Maßnahmen zur Einhaltung der Qualitätskriterien. | K8: Ein systematischer und strukturierter Ansatz zur Ermittlung und Dokumentation von Anforderungen ist vorhanden und wird unternehmensweit verfolg. Attributschema und Einbindung in den RE-Prozess sind klar definiert. Sowohl Interne als auch Externe nutzen dieses Attributschema. Der RE-Ansatz wird kontinuierlich optimiert.
B9: System-Architekturgestaltung | C9: Die Kompetenz die zu einem System zugehörigen Elemente, ihrer Hierarchie, sowie ihrer Schnittstellen oder ihres Verhaltens und der damit verbundenen abgeleiteten Anforderungen zur Entwicklung einer implementierbaren Lösung zu definieren. | D9: System-Architektur, Schnittstellen | F9: Die (System-) Architektur umfasst sowohl die Struktur als auch das Verhalten des Systems. Sie soll dabei einen konkreten Zweck erfüllen, z.B. die Beschreibung des Zusammenwirkens einzelner Systemelemente. Im Kontext des SE ist die Architektur Teil der Systemgestaltung. Dabei kann die Architektur tool-gestützt, (semi-) formal, durchgängig und rückverfolgbar gestaltet werden [Alt12], [HWF+19]. Die Architekturgestaltung wird durch verschiedene Methoden unterstützt. | G9: Das System wird nicht durch eine abstrakte und disziplinneutrale Architektur im Sinne des SE beschrieben. | H9: Einzelne Aspekte des Systems, wie z.B. die Wirkstruktur oder die Systemzustände, werden gem. einer SE-gerechten Architektur vorwiegend nach Bedarf beschrieben. Ein methodischer Ansatz wird dabei nicht (bewusst) verfolgt. | I9: In einzelnen Abteilungen erfolgt ein methodisches Vorgehen auf Basis des Systemdenkens, um einzelne Aspekte der Systemarchitektur systematisch zu erstellen. Die Systemarchitektur-gestaltung erfolgt auf Basis eines definierten Gedankenmodells (z.B. RFLP), um mit der Architekturgestaltung Mehrwerte für die Produktentwicklung zu heben. | J9: Die Systemarchitektur wird unternehmens-weit, ganzheitlich aus Sicht des Systems und semi-formal (z.B. mit SysML) mit Hilfe geeigneter Methoden beschrieben und analysiert. Für verschiedene Zwecke sind Viewpoints definiert. Es erfolgt eine logische Verknüpfung der einzelnen Aspekte z.B. zwischen funktionaler und physischer Architektur. Es werden alternative Lösungsmöglichkeiten betrachtet. | K9: Die Systemarchitektur wird formal durch eine bedarfsgerechte, angepasste Notation tool-gestützt beschrieben. Die Methoden sowie der Architekturgestaltungs-prozess werden regelmäßig evaluiert und angepasst.
B10: Integration, Verifikation & Validierung | C10: Die Kompetenz eine Menge von Systemelementen zu einer verifizier- oder validierbaren Einheit zu integrieren bzw. den objektiven Nachweis, das ein System die spezifizierten Anforderungen erfüllt (Validierung), oder seiner beabsichtigten Eigenschaften in der vorgesehenen Einsatzumgebung erreicht (Validierung), durchzuführen. | D10: Integration, Verifizierung, Validierung | F10: Beurteilung eines Produktes hinsichtlich spezifischer Produkteigenschaften (Verifikation) und der Einsetzbarkeit des Produktes (Validierung) | G10: Keine besondere Expertise hinsichtlich V&V-Techniken vorhanden. Es ist im Unternehmen keine unabhängige Testinstanz vorhanden. Testprozeduren sind nicht reproduzierbar. Eine Dokumentation findet nur rudimentär und mit stark aggregierten Ergebnissen statt. | H10: Es liegen teilweise reproduzierbare Testprozeduren vor. Es erfolgt eine individuelle Dokumentation und Ablage der V&V-Tätigkeiten. | I10: In vereinzelten Unternehmensbereichen werden V&V-Prozeduren standardisiert dokumentiert und innerhalb dieser Bereiche zentral bereitgestellt. Die Input-Parameter für die V&V-Prozeduren sind oftmals definiert (z.B. in Form von Anforderungen). | J10: Die V&V ist ein fester Bestandteil des Entwicklungsprozesses und wird von einer unabhängigen Testinstanz durchgeführt. Tiefe, spezialisierte V&V-Expertise ist vorhanden. Es werden überwiegend standardisierte Testprozeduren genutzt. Dokumentationen werden zentral bereitgestellt und sind über z.B. Projekt- oder Bauteilbezüge wieder auffindbar. Die Input-Parameter für die V&V-Prozeduren sind definiert. | K10: Das dokumentierte Wissen ist ohne kontextspezifisches Vorwissen auffindbar. Wo immer möglich, werden V&V-Prozeduren sowie -Dokumentationen wiederverwendet. Die Durchführung und Dokumentation von V&V-Tätigkeiten werden ständig weiteroptimiert.
B11: Betrieb, Service und Instandhaltung | C11: Die Kompetenz das System in Betrieb zu nehmen, zu betreiben und seine Fähigkeiten/Funktionalitäten über seine Lebensdauer aufrechterhalten wird. | D11: Überleitung, Betrieb und Support
B12: Agile Methodenkompetenz | C12: Die Kompetenz Methoden anzuwenden, welche die Agilenwerte im Projektkontext unterstützen und paralleles arbeiten ermöglichen | D12: Gleichzeitige-Entwicklung
A13: Sozial- und Selbstkompetenzen | B13: Selbstorganisation | C13: Die Kompetenz sich selbst zu organisieren und Aufgaben | D13: Veränderung, Selbstkompetenz, Selbstorganisation, Gleichzeitige Entwicklung
B14: Kommunikation & Zusammenarbeit | C14: Die Kompetenz konstruktiv, effizient und bewusst, auch domaineübergreifend, zu kommunizieren und dabei die Gefühle anderer Menschen zu erfassen und zu berücksichtzigen sowie Beziehungen zu Kollegen und Vorgesetzten nachhaltig und fair zu gestalten. | D14: Kommunikation, Ethik und Professionalität, Emotionale Intelligenz
B15: Führen | C15: Die Kompetenz geeignete Ziele für ein System bzw. Systemelement auszuwählen, bei Bedarf zu verhandeln und mit einem Team effizient zu erreichen und dabei ggf. Teammitglieder bei der Lösung von Problemen anzuleiten. | D15: Technische Führung, Unterstützung/ Vermittlung, Teamdynamik, Verhandlung, Coaching und Mentoring,
A16: Managementkompetenzen | B16: Projektmanagement | C16: Die Kompetenz Aktivitäten zu identifizieren, planen, koordinieren und anzupassen um ein zufriedenstellendes System, Produkt oder Service mit angemessener Qualität, Finanzen und Zeit zu liefern. | D16: Projektmanagement, Finanzen, Qualität, Planung, Überwachung und Steuerung , Gleichzeitige Entwicklung | F16: In der SE-Philosophie ist das Projektmanagement eng mit dem der Systemgestaltung des SE verknüpft. Für die erfolgreiche Entwicklung von Systemen ist es daher wichtig, dass SE bei der organisatorischen Projektplanung und -gestaltung berücksichtigt wird und einzelne Tätigkeiten beider Bereiche miteinander integriert und entsprechende Rollenkonzepte und Aufgabenbeschreibungen definiert, sowie abgegrenzt sind. | G16: Die Koordination, Gestaltung und Planung von SE-Prozessen werden im Rahmen des Projektmanagements nicht berücksichtigt. Die Tätigkeiten und Aufgaben des Projektmanagements sind dabei nicht mit denen des SE abgestimmt. | H16: In einigen SE-Pionier-Projekten erfolgt die Koordination, Gestaltung und Planung von SE-Prozessen im Rahmen des Projektmanagements. Die Tätigkeiten und Aufgaben des Projektmanagements sind dabei im gesamten Unternehmen noch nicht mit denen des SE abgestimmt. | I16: Die Koordination, Gestaltung und Planung von SE-Prozessen ist organisatorisch mit dem Projektmanagement verankert. In der Praxis sind die Tätigkeiten und Aufgaben des Projektmanagements dabei im gesamten Unternehmen noch nicht mit denen des SE abgestimmt. | J16: Die Koordination, Gestaltung und Planung von SE-Prozessen sind ein fester, gelebter Bestandteil des Projektmanagements. Die Tätigkeiten und Aufgaben des Projektmanagements sind dabei im gesamten Unternehmen mit denen des SE abgestimmt. | K16: Die Koordination, Gestaltung und Planung von SE-Prozessen werden als fester Bestandteil des Projektmanagements zusätzlich kontinuierlich an sich verändernde äußere Rahmenbedingungen angepasst und systematisch optimiert.
B17: Entscheidungsmanagement | C17: Die Kompetenz strukturiert und analytisch ein objektives Set von Alternativen zu identifizieren, zu charakterisieren und zu evaluieren und dabei Risiken und Chancen zu berücksichtigen | D17: Risiko- und Chancenmanagement
B18: Informationsmanagement | C18: Die Fähigkeit alle Aspekten von Informationen für bestimmte Stakeholder zu adressieren, um die richtigen Informationen zum passenden Zeitpunkt, in der passenden Sicherheit zu liefern. | D18: Beschaffung und Versorgung, Entwurf für...
B19: Konfigurationsmanagement | C19: Die Fähigkeit Systemfunktionen, Leistung und physikalischen Eigenschaften über den Lebenszyklus stimmig zu gestalten und die Konsistenz sicherzustellen.

Sheet Rollen-Prozess-Matrix
B1: Lifecyle-Prozess | C1: 0 = nicht relevant 1 = unterstützt 2 = verantwortlich 3= gestaltet | D1: Activity and Tasks (ISO 15288, 2015) | E1: Prozess | F1: Aktivität | G1: Erläuterung (als Satz) | H1: Kunde | I1: Kundenvertreter | J1: Projektleiter | K1: Interner Support (IT, Qualifikation, SE) | L1: Prozess- & Richtlinien-verantwortlicher​ | M1: System-Ingenieur | N1: Entwickler | O1: Produktionskoordinator/ -planer | P1: V&V-Mitarbeiter | Q1: Produktionsmitarbeiter | R1: Servicetechniker | S1: Qualitätsmanager | T1: Innovations- und (Strategie)management | U1: Management
A2: Anwendung | B2: 6.1 Vertrags-Prozesse | C2: Akquisition | D2: Prepare for the acquisition | E2: 6.1.1 Akquisition | F2: Vorbereiten der Anschaffung | H2: 0 | I2: 0 | J2: 0 | K2: 0 | L2: 3 | M2: 1 | N2: 1 | O2: 2 | P2: 1 | Q2: 0 | R2: 0 | S2: 0 | T2: 0 | U2: 0
C3: Lieferung | D3: Prepare for the supply | E3: 6.1.2 Lieferung | F3: Vorbereiten der Lieferung | H3: 0 | I3: 2 | J3: 1 | K3: 0 | L3: 3 | M3: 1 | N3: 0 | O3: 1 | P3: 0 | Q3: 0 | R3: 1 | S3: 0 | T3: 0 | U3: 0
B4: 6.2 Organisatorische Projektbefähigungs-Prozesse | C4: Lebenszyklus-Modell-Management | D4: Establish the process | E4: 6.2.1 Lebenszyklus-Modell-Management | F4: Definition eines Prozess | H4: 0 | I4: 0 | J4: 0 | K4: 1 | L4: 3 | M4: 0 | N4: 0 | O4: 0 | P4: 0 | Q4: 0 | R4: 0 | S4: 0 | T4: 0 | U4: 0
C5: Verwaltung der Infrastruktur | D5: Establish the infrastructure | E5: 6.2.2 Verwaltung der Infrastruktur | F5: Einrichten der Infrastruktur | H5: 0 | I5: 0 | J5: 0 | K5: 2 | L5: 3 | M5: 0 | N5: 0 | O5: 0 | P5: 0 | Q5: 0 | R5: 0 | S5: 0 | T5: 0 | U5: 0
C6: Portfoliomanagement | D6: Define and authorize projects | E6: 6.2.3 Portfoliomanagement | F6: Definition und Genehmigung von Projekten | H6: 0 | I6: 1 | J6: 1 | K6: 0 | L6: 3 | M6: 0 | N6: 0 | O6: 0 | P6: 0 | Q6: 0 | R6: 0 | S6: 0 | T6: 2 | U6: 1
C7: Personalwesen-Management | D7: Identify skills | E7: 6.2.4 Personalwesen-Management | F7: Idenfizierung von Fähigkeiten | H7: 0 | I7: 0 | J7: 0 | K7: 2 | L7: 3 | M7: 0 | N7: 0 | O7: 0 | P7: 0 | Q7: 0 | R7: 0 | S7: 0 | T7: 0 | U7: 1
C8: Qualitätsmanagement | D8: Plan quality management | E8: 6.2.5 Qualitätsmanagement | F8: Planung des Qualitätsmanagement | H8: 0 | I8: 0 | J8: 0 | K8: 0 | L8: 3 | M8: 0 | N8: 0 | O8: 0 | P8: 1 | Q8: 0 | R8: 0 | S8: 2 | T8: 0 | U8: 0
C9: Wissensmanagement | D9: Plan knowledge management | E9: 6.2.6 Wissensmanagement | F9: Planung des Wissensmanagement | H9: 0 | I9: 0 | J9: 0 | K9: 2 | L9: 3 | M9: 0 | N9: 0 | O9: 0 | P9: 0 | Q9: 0 | R9: 0 | S9: 0 | T9: 0 | U9: 0
B10: 6.3 Technischen Management Prozesse | C10: Projektierung/Projektplanung | D10: Define the project | E10: 6.3.1 Projektierung/Projektplanung | F10: Definieren des Projekts | H10: 0 | I10: 0 | J10: 2 | K10: 0 | L10: 3 | M10: 0 | N10: 0 | O10: 0 | P10: 0 | Q10: 0 | R10: 0 | S10: 0 | T10: 0 | U10: 0
C11: Projektbewertung und Steuerung | D11: Plan for project assesment and control | E11: 6.3.2 Projektbewertung und Steuerung | F11: Planung zur Projektbewertung und -steuerung | H11: 0 | I11: 0 | J11: 2 | K11: 0 | L11: 3 | M11: 0 | N11: 0 | O11: 0 | P11: 0 | Q11: 0 | R11: 0 | S11: 0 | T11: 0 | U11: 1
C12: Entscheidungsmanagement | D12: Prepare for decisions | E12: 6.3.3 Entscheidungs-management | F12: Vorbereiten der Entscheidungen | H12: 0 | I12: 2 | J12: 2 | K12: 0 | L12: 3 | M12: 2 | N12: 1 | O12: 1 | P12: 1 | Q12: 0 | R12: 0 | S12: 0 | T12: 1 | U12: 2
C13: Risiko-Management | D13: Plan risk management | E13: 6.3.4 Risiko-Management | F13: Risikomanagement planen | H13: 0 | I13: 1 | J13: 2 | K13: 0 | L13: 3 | M13: 2 | N13: 1 | O13: 1 | P13: 0 | Q13: 0 | R13: 0 | S13: 1 | T13: 0 | U13: 0
C14: Konfigurationsmanagement | D14: Plan configuration management | E14: 6.3.5 Konfigurationsmanagement (Änderungsmanagement) | F14: Konfigurationsmanagement planen | H14: 0 | I14: 1 | J14: 2 | K14: 0 | L14: 3 | M14: 2 | N14: 1 | O14: 0 | P14: 1 | Q14: 0 | R14: 0 | S14: 0 | T14: 0 | U14: 0
C15: Informationsmanagement | D15: Prepare for information management | E15: 6.3.6 Informationsmanagement | F15: Informationsmanagement vorbereiten | H15: 0 | I15: 1 | J15: 2 | K15: 0 | L15: 3 | M15: 1 | N15: 1 | O15: 0 | P15: 1 | Q15: 0 | R15: 0 | S15: 0 | T15: 0 | U15: 0
C16: Messung | D16: Prepare for measurement | E16: 6.3.7 Messung | F16: Vorbereiten der Messung | H16: 0 | I16: 0 | J16: 0 | K16: 0 | L16: 3 | M16: 0 | N16: 1 | O16: 0 | P16: 2 | Q16: 0 | R16: 0 | S16: 0 | T16: 0 | U16: 0
C17: Qualitätssicherungsprozess | D17: Prepare for quality assurance | E17: 6.3.8 Qualitätssicherungsprozess | F17: Vorbereiten der Qualitätssicherung | H17: 0 | I17: 1 | J17: 1 | K17: 0 | L17: 3 | M17: 0 | N17: 0 | O17: 0 | P17: 2 | Q17: 0 | R17: 0 | S17: 2 | T17: 0 | U17: 0
B18: 6.4 Technische Prozesse | C18: Geschäfts- oder Einsatzanalyseprozess: | D18: Prepare for business or mission analysis | E18: 6.4.1 Geschäfts- oder Einsatzanalyseprozess: | F18: Vorbereiten der Geschäfts- oder Einsatzanalyse | H18: 0 | I18: 2 | J18: 0 | K18: 0 | L18: 3 | M18: 0 | N18: 0 | O18: 0 | P18: 0 | Q18: 0 | R18: 0 | S18: 0 | T18: 2 | U18: 1
C19: Prozess der Stakeholder-Bedürfnisse und Anforderungsdefinition: | D19: Prepare the stakeholder needs and requirements definition | E19: 6.4.2 Prozess der Stakeholder-Bedürfnisse und Anforderungsdefinition: | F19: Vorbereiten der Bedarfsanalyse und Anforderungsdefinition der Stakeholder | G19: Es sollen die Anfordernungen der Stakeholderaufgedeckt werden. Dazu sind zunächst alle Stakeholder zu ermitteln und im Nachgang deren Anforderungen an das System. | H19: 0 | I19: 2 | J19: 0 | K19: 0 | L19: 3 | M19: 1 | N19: 0 | O19: 0 | P19: 1 | Q19: 0 | R19: 0 | S19: 0 | T19: 0 | U19: 0
C20: Prozess der Definition von Systemanforderungen: | D20: Prepare for systems requirements definitions | E20: 6.4.3 Prozess der Definition von Systemanforderungen: | F20: Vorbereiten von Systemanforderungsdefinitionen | H20: 0 | I20: 2 | J20: 0 | K20: 0 | L20: 3 | M20: 2 | N20: 1 | O20: 0 | P20: 1 | Q20: 0 | R20: 0 | S20: 0 | T20: 0 | U20: 0
C21: Prozess der Architekturdefinition: | D21: Prepare for architecture definition | E21: 6.4.4 Prozess der Architekturdefinition: | F21: Vorbereiten der Architekturdefinition | H21: 0 | I21: 1 | J21: 0 | K21: 0 | L21: 3 | M21: 2 | N21: 1 | O21: 0 | P21: 0 | Q21: 0 | R21: 0 | S21: 0 | T21: 0 | U21: 0
C22: Prozess der Designdefinition: | D22: Prepare for design definitions | E22: 6.4.5 Prozess der Designdefinition: | F22: Vorbereiten von Entwurfsdefinitionen | H22: 0 | I22: 1 | J22: 0 | K22: 0 | L22: 3 | M22: 2 | N22: 2 | O22: 0 | P22: 0 | Q22: 0 | R22: 0 | S22: 0 | T22: 0 | U22: 0
C23: Prozess der Systemanalyse: | D23: Prepare for systems analysis | E23: 6.4.6 Prozess der Systemanalyse: | F23: Vorbereiten der Systemanalyse | H23: 0 | I23: 0 | J23: 0 | K23: 0 | L23: 3 | M23: 1 | N23: 0 | O23: 0 | P23: 2 | Q23: 0 | R23: 0 | S23: 0 | T23: 0 | U23: 0
C24: Umsetzungsprozess: | D24: Prepare for implementation | E24: 6.4.7 Umsetzungsprozess: | F24: Vorbereiten der Umsetzung | G24: Die Umsetzung wird geplant, indem eine Umsetzungsstrategie erarbeitet wird, d.h. es wird definiert, welches Herstellverfahren verwendet wird, welche Werkzeuge und Fertigungstoleranzen gewählt werden. | H24: 0 | I24: 0 | J24: 0 | K24: 0 | L24: 3 | M24: 0 | N24: 2 | O24: 2 | P24: 0 | Q24: 2 | R24: 0 | S24: 0 | T24: 0 | U24: 0
C25: Integrationsprozess: | D25: Prepare for integration | E25: 6.4.8 Integrationsprozess: | F25: Vorbereiten der Integration | G25: Eine Integrationsstrategie wird erarbeitet. Prüfwerkzeugen und -Einrichtungen für die Integration werden reserviert. | H25: 0 | I25: 1 | J25: 0 | K25: 0 | L25: 3 | M25: 0 | N25: 0 | O25: 1 | P25: 1 | Q25: 2 | R25: 0 | S25: 0 | T25: 0 | U25: 0
C26: Verifikationsprozess: | D26: Prepare for verification | E26: 6.4.9 Verifikationsprozess: | F26: Vorbereiten der Verifikation | G26: Verfikationstätigkeiten und zugehörige Rollen und Verantwortlichkeiten werden geplant. | H26: 0 | I26: 1 | J26: 0 | K26: 0 | L26: 3 | M26: 1 | N26: 1 | O26: 0 | P26: 2 | Q26: 0 | R26: 0 | S26: 1 | T26: 0 | U26: 0
C27: Übergabeprozess: | D27: Prepare for the transition | E27: 6.4.10 Übergabeprozess: | F27: Vorbereiten der Übergabe | G27: Installationsverfahren/ eine Übergabestrategie wird ausgearbeitet. Inhalten zur Schulung des Bedienpersonals, Logistikunterstützung, Auslieferung und Problembehebung bzw. Problemlösung müssen erarbeitet werden. | H27: 2 | I27: 2 | J27: 0 | K27: 0 | L27: 3 | M27: 0 | N27: 0 | O27: 2 | P27: 0 | Q27: 0 | R27: 2 | S27: 0 | T27: 0 | U27: 0
C28: Validierungsprozess: | D28: Prepare for validation | E28: 6.4.11 Validierungsprozess: | F28: Vorbereiten der Validierung | G28: Eine Validierungsstrategie wird entwickelt. | H28: 1 | I28: 1 | J28: 0 | K28: 0 | L28: 3 | M28: 0 | N28: 0 | O28: 0 | P28: 2 | Q28: 0 | R28: 0 | S28: 1 | T28: 0 | U28: 0
C29: Betriebsprozess: | D29: Prepare for operation | E29: 6.4.12 Betriebsprozess: | F29: Vorbereiten auf den Betrieb | G29: Vorbereitung auf den Betrieb. | H29: 2 | I29: 0 | J29: 0 | K29: 0 | L29: 3 | M29: 1 | N29: 0 | O29: 0 | P29: 0 | Q29: 0 | R29: 1 | S29: 0 | T29: 0 | U29: 0
C30: Wartungsprozess: | D30: Prepare for maintenance | E30: 6.4.13 Wartungsprozess: | F30: Vorbereiten der Wartung | G30: Eine Wartungsstrategie wird erarbeitet. Ersatzteilbestände werden überwacht und ausgebildetes Wartungspersonal wird koordiniert. | H30: 2 | I30: 0 | J30: 0 | K30: 0 | L30: 3 | M30: 1 | N30: 0 | O30: 0 | P30: 0 | Q30: 0 | R30: 2 | S30: 0 | T30: 0 | U30: 0
C31: Entsorgungsprozess: | D31: Prepare for disposal | E31: 6.4.14 Entsorgungsprozess: | F31: Vorbereitung der Entsorgung | G31: Die Entsorgungsstrategie wird geplant und das Konzept begutachtet. | H31: 2 | I31: 0 | J31: 0 | K31: 0 | L31: 3 | M31: 0 | N31: 0 | O31: 0 | P31: 0 | Q31: 0 | R31: 1 | S31: 0 | T31: 0 | U31: 0
A32: Support | B32: Weitere | C32: Support | F32: Aufnahme von Support-Anfragen/Problemen/Herausforderungen bzgl. SE-Methoden oder Tools | H32: 0 | I32: 0 | J32: 0 | K32: 2 | L32: 1 | M32: 0 | N32: 0 | O32: 0 | P32: 0 | Q32: 0 | R32: 0 | S32: 0 | T32: 0 | U32: 0
A33: Moderation | C33: Moderation | F33: Festlegen von Teilnehmer, Ziele und Agenda von (SE-) Workshops oder anderen Terminen | H33: 0 | I33: 0 | J33: 2 | K33: 2 | L33: 0 | M33: 2 | N33: 1 | O33: 0 | P33: 1 | Q33: 0 | R33: 0 | S33: 0 | T33: 0 | U33: 0
A34: Qualifikation | C34: Qualifizierung | E34: Schulung | F34: Schulungsbedarf feststellen, Qualifikatonslevel der Abteilungen ableiten | H34: 0 | I34: 0 | J34: 0 | K34: 2 | L34: 0 | M34: 0 | N34: 0 | O34: 0 | P34: 0 | Q34: 0 | R34: 0 | S34: 0 | T34: 0 | U34: 0

Sheet Kompetenz-Prozess-Matrix
B4: 0 = nicht relevant 1 = sinnvoll 2 = notwendig Prozess der ISO 15288 | D4: Kern Kompetenzen | H4: Fachkompetenzen | M4: Sozial- und Selbstkompetenzen | P4: Management- kompetenzen | X4: Kern Kompetenzen | AB4: Fachkompetenzen | AG4: Sozial- und Selbstkompetenzen | AJ4: Management- kompetenzen
D5: Systemisches Denken | E5: Systemmodellierung und -analyse | F5: Berücksichtigung von Systemlebenszyklusphasen | G5: Agiles Denken / Kunden-Nutzenorientierung | H5: Anforderungsmanagement | I5: System-Architekturgestaltung | J5: Integration, Verifikation & Validierung | K5: Betrieb, Service und Instandhaltung | L5: Agile Methodenkompetenz | M5: Selbstorganisation | N5: Kommunikation & Zusammenarbeit | O5: Führen | P5: Projektmanagement | Q5: Entscheidungsmanagement | R5: Informationsmanagement | S5: Konfigurationsmanagement | V5: Indivudual User | X5: Systemisches Denken | Y5: Systemmodellierung und -analyse | Z5: Berücksichtigung von Systemlebenszyklusphasen | AA5: Agiles Denken / Kunden-Nutzenorientierung | AB5: Anforderungsmanagement | AC5: System-Architekturgestaltung | AD5: Integration, Verifikation & Validierung | AE5: Betrieb, Service und Instandhaltung | AF5: Agile Methodenkompetenz | AG5: Selbstorganisation | AH5: Kommunikation & Zusammenarbeit | AI5: Führen | AJ5: Projektmanagement | AK5: Entscheidungsmanagement | AL5: Informationsmanagement | AM5: Konfigurationsmanagement | AN5: Highest
B6: Akquisition | C6: Vorbereiten der Anschaffung | D6: 1 | E6: 0 | F6: 0 | G6: 0 | H6: 1 | I6: 0 | J6: 0 | K6: 0 | L6: 0 | M6: 1 | N6: 2 | O6: 0 | P6: 0 | Q6: 0 | R6: 0 | S6: 0 | V6: 0 | X6: =D6*$V6 -> 0 | Y6: =E6*$V6 -> 0 | Z6: =F6*$V6 -> 0 | AA6: =G6*$V6 -> 0 | AB6: =H6*$V6 -> 0 | AC6: =I6*$V6 -> 0 | AD6: =J6*$V6 -> 0 | AE6: =K6*$V6 -> 0 | ... AM6: =S6*$V6 -> 0 | AN6: =MAX(X6:AM6) -> 0
B7: Lieferung | C7: Vorbereiten der Lieferung | D7: 1 | E7: 0 | F7: 0 | G7: 0 | H7: 1 | I7: 0 | J7: 0 | K7: 0 | L7: 0 | M7: 1 | N7: 2 | O7: 0 | P7: 0 | Q7: 0 | R7: 0 | S7: 0 | V7: 0 | X7: =D7*$V7 -> 0 | Y7: =E7*$V7 -> 0 | Z7: =F7*$V7 -> 0 | AA7: =G7*$V7 -> 0 | AB7: =H7*$V7 -> 0 | AC7: =I7*$V7 -> 0 | AD7: =J7*$V7 -> 0 | AE7: =K7*$V7 -> 0 | ... AM7: =S7*$V7 -> 0 | AN7: =MAX(X7:AM7) -> 0
B8: Lebenszyklus-Modell-Management | C8: Definition eines Prozess | D8: 2 | E8: 2 | F8: 2 | G8: 1 | H8: 2 | I8: 2 | J8: 2 | K8: 2 | L8: 2 | M8: 1 | N8: 0 | O8: 0 | P8: 2 | Q8: 2 | R8: 2 | S8: 2 | V8: 0 | X8: =D8*$V8 -> 0 | Y8: =E8*$V8 -> 0 | Z8: =F8*$V8 -> 0 | AA8: =G8*$V8 -> 0 | AB8: =H8*$V8 -> 0 | AC8: =I8*$V8 -> 0 | AD8: =J8*$V8 -> 0 | AE8: =K8*$V8 -> 0 | ... AM8: =S8*$V8 -> 0 | AN8: =MAX(X8:AM8) -> 0
B9: Verwaltung der Infrastruktur | C9: Einrichten der Infrastruktur | D9: 1 | E9: 1 | F9: 0 | G9: 0 | H9: 1 | I9: 1 | J9: 0 | K9: 0 | L9: 0 | M9: 1 | N9: 1 | O9: 1 | P9: 0 | Q9: 1 | R9: 1 | S9: 1 | V9: 0 | X9: =D9*$V9 -> 0 | Y9: =E9*$V9 -> 0 | Z9: =F9*$V9 -> 0 | AA9: =G9*$V9 -> 0 | AB9: =H9*$V9 -> 0 | AC9: =I9*$V9 -> 0 | AD9: =J9*$V9 -> 0 | AE9: =K9*$V9 -> 0 | ... AM9: =S9*$V9 -> 0 | AN9: =MAX(X9:AM9) -> 0
B10: Portfoliomanagement | C10: Definition und Genehmigung von Projekten | D10: 1 | E10: 0 | F10: 0 | G10: 0 | H10: 0 | I10: 0 | J10: 0 | K10: 0 | L10: 0 | M10: 1 | N10: 1 | O10: 2 | P10: 1 | Q10: 2 | R10: 0 | S10: 0 | V10: 2 | X10: =D10*$V10 -> 2 | Y10: =E10*$V10 -> 0 | Z10: =F10*$V10 -> 0 | AA10: =G10*$V10 -> 0 | AB10: =H10*$V10 -> 0 | AC10: =I10*$V10 -> 0 | AD10: =J10*$V10 -> 0 | AE10: =K10*$V10 -> 0 | ... AM10: =S10*$V10 -> 0 | AN10: =MAX(X10:AM10) -> 4
B11: Personalwesen-Management | C11: Idenfizierung von Fähigkeiten | D11: 1 | E11: 1 | F11: 1 | G11: 0 | H11: 0 | I11: 0 | J11: 0 | K11: 0 | L11: 0 | M11: 1 | N11: 1 | O11: 1 | P11: 0 | Q11: 0 | R11: 0 | S11: 0 | V11: 0 | X11: =D11*$V11 -> 0 | Y11: =E11*$V11 -> 0 | Z11: =F11*$V11 -> 0 | AA11: =G11*$V11 -> 0 | AB11: =H11*$V11 -> 0 | AC11: =I11*$V11 -> 0 | AD11: =J11*$V11 -> 0 | AE11: =K11*$V11 -> 0 | ... AM11: =S11*$V11 -> 0 | AN11: =MAX(X11:AM11) -> 0
B12: Qualitätsmanagement | C12: Planung des Qualitätsmanagement | D12: 1 | E12: 1 | F12: 1 | G12: 0 | H12: 2 | I12: 2 | J12: 0 | K12: 0 | L12: 0 | M12: 1 | N12: 1 | O12: 1 | P12: 2 | Q12: 0 | R12: 0 | S12: 0 | V12: 0 | X12: =D12*$V12 -> 0 | Y12: =E12*$V12 -> 0 | Z12: =F12*$V12 -> 0 | AA12: =G12*$V12 -> 0 | AB12: =H12*$V12 -> 0 | AC12: =I12*$V12 -> 0 | AD12: =J12*$V12 -> 0 | AE12: =K12*$V12 -> 0 | ... AM12: =S12*$V12 -> 0 | AN12: =MAX(X12:AM12) -> 0
B13: Wissensmanagement | C13: Planung des Wissensmanagement | D13: 1 | E13: 1 | F13: 0 | G13: 0 | H13: 0 | I13: 1 | J13: 0 | K13: 0 | L13: 0 | M13: 1 | N13: 1 | O13: 1 | P13: 0 | Q13: 0 | R13: 2 | S13: 0 | V13: 0 | X13: =D13*$V13 -> 0 | Y13: =E13*$V13 -> 0 | Z13: =F13*$V13 -> 0 | AA13: =G13*$V13 -> 0 | AB13: =H13*$V13 -> 0 | AC13: =I13*$V13 -> 0 | AD13: =J13*$V13 -> 0 | AE13: =K13*$V13 -> 0 | ... AM13: =S13*$V13 -> 0 | AN13: =MAX(X13:AM13) -> 0
B14: Projektierung/Projektplanung | C14: Definieren des Projekts | D14: 2 | E14: 0 | F14: 1 | G14: 2 | H14: 1 | I14: 1 | J14: 1 | K14: 1 | L14: 2 | M14: 2 | N14: 2 | O14: 2 | P14: 2 | Q14: 1 | R14: 1 | S14: 0 | V14: 0 | X14: =D14*$V14 -> 0 | Y14: =E14*$V14 -> 0 | Z14: =F14*$V14 -> 0 | AA14: =G14*$V14 -> 0 | AB14: =H14*$V14 -> 0 | AC14: =I14*$V14 -> 0 | AD14: =J14*$V14 -> 0 | AE14: =K14*$V14 -> 0 | ... AM14: =S14*$V14 -> 0 | AN14: =MAX(X14:AM14) -> 0
B15: Projektbewertung und Steuerung | C15: Planung zur Projektbewertung und -steuerung | D15: 1 | E15: 0 | F15: 1 | G15: 2 | H15: 1 | I15: 1 | J15: 1 | K15: 1 | L15: 2 | M15: 2 | N15: 2 | O15: 2 | P15: 2 | Q15: 1 | R15: 1 | S15: 0 | V15: 2 | X15: =D15*$V15 -> 2 | Y15: =E15*$V15 -> 0 | Z15: =F15*$V15 -> 2 | AA15: =G15*$V15 -> 4 | AB15: =H15*$V15 -> 2 | AC15: =I15*$V15 -> 2 | AD15: =J15*$V15 -> 2 | AE15: =K15*$V15 -> 2 | ... AM15: =S15*$V15 -> 0 | AN15: =MAX(X15:AM15) -> 4
B16: Entscheidungsmanagement | C16: Vorbereiten der Entscheidungen | D16: 1 | E16: 1 | F16: 2 | G16: 1 | H16: 0 | I16: 0 | J16: 0 | K16: 0 | L16: 0 | M16: 1 | N16: 1 | O16: 1 | P16: 1 | Q16: 2 | R16: 0 | S16: 0 | V16: 0 | X16: =D16*$V16 -> 0 | Y16: =E16*$V16 -> 0 | Z16: =F16*$V16 -> 0 | AA16: =G16*$V16 -> 0 | AB16: =H16*$V16 -> 0 | AC16: =I16*$V16 -> 0 | AD16: =J16*$V16 -> 0 | AE16: =K16*$V16 -> 0 | ... AM16: =S16*$V16 -> 0 | AN16: =MAX(X16:AM16) -> 0
B17: Risiko-Management | C17: Risikomanagement planen | D17: 1 | E17: 2 | F17: 2 | G17: 1 | H17: 1 | I17: 0 | J17: 0 | K17: 0 | L17: 0 | M17: 1 | N17: 1 | O17: 1 | P17: 1 | Q17: 2 | R17: 1 | S17: 0 | V17: 0 | X17: =D17*$V17 -> 0 | Y17: =E17*$V17 -> 0 | Z17: =F17*$V17 -> 0 | AA17: =G17*$V17 -> 0 | AB17: =H17*$V17 -> 0 | AC17: =I17*$V17 -> 0 | AD17: =J17*$V17 -> 0 | AE17: =K17*$V17 -> 0 | ... AM17: =S17*$V17 -> 0 | AN17: =MAX(X17:AM17) -> 0
... B38: Qualifizierung | C38: Schulungsbedarf feststellen, Qualifikatonslevel der Abteilungen ableiten | D38: 2 | E38: 2 | F38: 1 | G38: 2 | H38: 2 | I38: 2 | J38: 2 | K38: 2 | L38: 2 | M38: 2 | N38: 2 | O38: 2 | P38: 2 | Q38: 2 | R38: 2 | S38: 2 | V38: 0 | X38: =D38*$V38 -> 0 | Y38: =E38*$V38 -> 0 | Z38: =F38*$V38 -> 0 | AA38: =G38*$V38 -> 0 | AB38: =H38*$V38 -> 0 | AC38: =I38*$V38 -> 0 | AD38: =J38*$V38 -> 0 | AE38: =K38*$V38 -> 0 | ... AM38: =S38*$V38 -> 0 | AN38: =MAX(X38:AM38) -> 0

Sheet Rollen-Kompetenzen-Matrix
B2: 0 = nicht relevant 1 = anwenden 2 = verstehen 3/4 = anwenden 6 = beherrschen | D2: Kunde | E2: Kundenvertreter | F2: Projektleiter | G2: Interner Support (IT, Qualifikation, SE) | H2: Prozess- & Richtlinien-verantwortlicher​ | I2: System-Ingenieur | J2: Entwickler | K2: Produktionskoordinator/ -planer | L2: V&V-Mitarbeiter | M2: Produktionsmitarbeiter | N2: Servicetechniker | O2: Qualitätsmanager | P2: Innovations- und (Strategie)management | Q2: Management | S2: Anmerkung Leaderschulung
A3: Kern Kompetenzen | B3: Systemisches Denken | D3: =MAX(D4:D36) -> 2 | E3: =MAX(E4:E36) -> 4 | F3: =MAX(F4:F36) -> 4 | G3: =MAX(G4:G36) -> 4 | H3: =MAX(H4:H36) -> 6 | I3: =MAX(I4:I36) -> 4 | J3: =MAX(J4:J36) -> 2 | K3: =MAX(K4:K36) -> 2 | ... Q3: =MAX(Q4:Q36) -> 2 | S3: 2
C4: 6.1.1 Akquisition | D4: =PRODUCT('Rollen-Prozess-Matrix'!H2,'Kompetenz-Prozess-Matrix'!D6) -> 0 | E4: =PRODUCT('Rollen-Prozess-Matrix'!I2,'Kompetenz-Prozess-Matrix'!D6) -> 0 | F4: =PRODUCT('Rollen-Prozess-Matrix'!J2,'Kompetenz-Prozess-Matrix'!D6) -> 0 | G4: =PRODUCT('Rollen-Prozess-Matrix'!K2,'Kompetenz-Prozess-Matrix'!D6) -> 0 | H4: =PRODUCT('Rollen-Prozess-Matrix'!L2,'Kompetenz-Prozess-Matrix'!D6) -> 3 | I4: =PRODUCT('Rollen-Prozess-Matrix'!M2,'Kompetenz-Prozess-Matrix'!D6) -> 1 | J4: =PRODUCT('Rollen-Prozess-Matrix'!N2,'Kompetenz-Prozess-Matrix'!D6) -> 1 | K4: =PRODUCT('Rollen-Prozess-Matrix'!O2,'Kompetenz-Prozess-Matrix'!D6) -> 2 | L4: =PRODUCT('Rollen-Prozess-Matrix'!P2,'Kompetenz-Prozess-Matrix'!D6) -> 1 | M4: =PRODUCT('Rollen-Prozess-Matrix'!Q2,'Kompetenz-Prozess-Matrix'!D6) -> 0 | N4: =PRODUCT('Rollen-Prozess-Matrix'!R2,'Kompetenz-Prozess-Matrix'!D6) -> 0 | O4: =PRODUCT('Rollen-Prozess-Matrix'!S2,'Kompetenz-Prozess-Matrix'!D6) -> 0 | P4: =PRODUCT('Rollen-Prozess-Matrix'!T2,'Kompetenz-Prozess-Matrix'!D6) -> 0 | Q4: =PRODUCT('Rollen-Prozess-Matrix'!U2,'Kompetenz-Prozess-Matrix'!D6) -> 0
C5: 6.1.2 Lieferung | D5: =PRODUCT('Rollen-Prozess-Matrix'!H3,'Kompetenz-Prozess-Matrix'!D7) -> 0 | E5: =PRODUCT('Rollen-Prozess-Matrix'!I3,'Kompetenz-Prozess-Matrix'!D7) -> 2 | F5: =PRODUCT('Rollen-Prozess-Matrix'!J3,'Kompetenz-Prozess-Matrix'!D7) -> 1 | G5: =PRODUCT('Rollen-Prozess-Matrix'!K3,'Kompetenz-Prozess-Matrix'!D7) -> 0 | H5: =PRODUCT('Rollen-Prozess-Matrix'!L3,'Kompetenz-Prozess-Matrix'!D7) -> 3 | I5: =PRODUCT('Rollen-Prozess-Matrix'!M3,'Kompetenz-Prozess-Matrix'!D7) -> 1 | J5: =PRODUCT('Rollen-Prozess-Matrix'!N3,'Kompetenz-Prozess-Matrix'!D7) -> 0 | K5: =PRODUCT('Rollen-Prozess-Matrix'!O3,'Kompetenz-Prozess-Matrix'!D7) -> 1 | L5: =PRODUCT('Rollen-Prozess-Matrix'!P3,'Kompetenz-Prozess-Matrix'!D7) -> 0 | M5: =PRODUCT('Rollen-Prozess-Matrix'!Q3,'Kompetenz-Prozess-Matrix'!D7) -> 0 | N5: =PRODUCT('Rollen-Prozess-Matrix'!R3,'Kompetenz-Prozess-Matrix'!D7) -> 1 | O5: =PRODUCT('Rollen-Prozess-Matrix'!S3,'Kompetenz-Prozess-Matrix'!D7) -> 0 | P5: =PRODUCT('Rollen-Prozess-Matrix'!T3,'Kompetenz-Prozess-Matrix'!D7) -> 0 | Q5: =PRODUCT('Rollen-Prozess-Matrix'!U3,'Kompetenz-Prozess-Matrix'!D7) -> 0
C6: 6.2.1 Lebenszyklus-Modell-Management | D6: =PRODUCT('Rollen-Prozess-Matrix'!H4,'Kompetenz-Prozess-Matrix'!D8) -> 0 | E6: =PRODUCT('Rollen-Prozess-Matrix'!I4,'Kompetenz-Prozess-Matrix'!D8) -> 0 | F6: =PRODUCT('Rollen-Prozess-Matrix'!J4,'Kompetenz-Prozess-Matrix'!D8) -> 0 | G6: =PRODUCT('Rollen-Prozess-Matrix'!K4,'Kompetenz-Prozess-Matrix'!D8) -> 2 | H6: =PRODUCT('Rollen-Prozess-Matrix'!L4,'Kompetenz-Prozess-Matrix'!D8) -> 6 | I6: =PRODUCT('Rollen-Prozess-Matrix'!M4,'Kompetenz-Prozess-Matrix'!D8) -> 0 | J6: =PRODUCT('Rollen-Prozess-Matrix'!N4,'Kompetenz-Prozess-Matrix'!D8) -> 0 | K6: =PRODUCT('Rollen-Prozess-Matrix'!O4,'Kompetenz-Prozess-Matrix'!D8) -> 0 | L6: =PRODUCT('Rollen-Prozess-Matrix'!P4,'Kompetenz-Prozess-Matrix'!D8) -> 0 | M6: =PRODUCT('Rollen-Prozess-Matrix'!Q4,'Kompetenz-Prozess-Matrix'!D8) -> 0 | N6: =PRODUCT('Rollen-Prozess-Matrix'!R4,'Kompetenz-Prozess-Matrix'!D8) -> 0 | O6: =PRODUCT('Rollen-Prozess-Matrix'!S4,'Kompetenz-Prozess-Matrix'!D8) -> 0 | P6: =PRODUCT('Rollen-Prozess-Matrix'!T4,'Kompetenz-Prozess-Matrix'!D8) -> 0 | Q6: =PRODUCT('Rollen-Prozess-Matrix'!U4,'Kompetenz-Prozess-Matrix'!D8) -> 0
C7: 6.2.2 Verwaltung der Infrastruktur | D7: =PRODUCT('Rollen-Prozess-Matrix'!H5,'Kompetenz-Prozess-Matrix'!D9) -> 0 | E7: =PRODUCT('Rollen-Prozess-Matrix'!I5,'Kompetenz-Prozess-Matrix'!D9) -> 0 | F7: =PRODUCT('Rollen-Prozess-Matrix'!J5,'Kompetenz-Prozess-Matrix'!D9) -> 0 | G7: =PRODUCT('Rollen-Prozess-Matrix'!K5,'Kompetenz-Prozess-Matrix'!D9) -> 2 | H7: =PRODUCT('Rollen-Prozess-Matrix'!L5,'Kompetenz-Prozess-Matrix'!D9) -> 3 | I7: =PRODUCT('Rollen-Prozess-Matrix'!M5,'Kompetenz-Prozess-Matrix'!D9) -> 0 | J7: =PRODUCT('Rollen-Prozess-Matrix'!N5,'Kompetenz-Prozess-Matrix'!D9) -> 0 | K7: =PRODUCT('Rollen-Prozess-Matrix'!O5,'Kompetenz-Prozess-Matrix'!D9) -> 0 | L7: =PRODUCT('Rollen-Prozess-Matrix'!P5,'Kompetenz-Prozess-Matrix'!D9) -> 0 | M7: =PRODUCT('Rollen-Prozess-Matrix'!Q5,'Kompetenz-Prozess-Matrix'!D9) -> 0 | N7: =PRODUCT('Rollen-Prozess-Matrix'!R5,'Kompetenz-Prozess-Matrix'!D9) -> 0 | O7: =PRODUCT('Rollen-Prozess-Matrix'!S5,'Kompetenz-Prozess-Matrix'!D9) -> 0 | P7: =PRODUCT('Rollen-Prozess-Matrix'!T5,'Kompetenz-Prozess-Matrix'!D9) -> 0 | Q7: =PRODUCT('Rollen-Prozess-Matrix'!U5,'Kompetenz-Prozess-Matrix'!D9) -> 0
C8: 6.2.3 Portfoliomanagement | D8: =PRODUCT('Rollen-Prozess-Matrix'!H6,'Kompetenz-Prozess-Matrix'!D10) -> 0 | E8: =PRODUCT('Rollen-Prozess-Matrix'!I6,'Kompetenz-Prozess-Matrix'!D10) -> 1 | F8: =PRODUCT('Rollen-Prozess-Matrix'!J6,'Kompetenz-Prozess-Matrix'!D10) -> 1 | G8: =PRODUCT('Rollen-Prozess-Matrix'!K6,'Kompetenz-Prozess-Matrix'!D10) -> 0 | H8: =PRODUCT('Rollen-Prozess-Matrix'!L6,'Kompetenz-Prozess-Matrix'!D10) -> 3 | I8: =PRODUCT('Rollen-Prozess-Matrix'!M6,'Kompetenz-Prozess-Matrix'!D10) -> 0 | J8: =PRODUCT('Rollen-Prozess-Matrix'!N6,'Kompetenz-Prozess-Matrix'!D10) -> 0 | K8: =PRODUCT('Rollen-Prozess-Matrix'!O6,'Kompetenz-Prozess-Matrix'!D10) -> 0 | L8: =PRODUCT('Rollen-Prozess-Matrix'!P6,'Kompetenz-Prozess-Matrix'!D10) -> 0 | M8: =PRODUCT('Rollen-Prozess-Matrix'!Q6,'Kompetenz-Prozess-Matrix'!D10) -> 0 | N8: =PRODUCT('Rollen-Prozess-Matrix'!R6,'Kompetenz-Prozess-Matrix'!D10) -> 0 | O8: =PRODUCT('Rollen-Prozess-Matrix'!S6,'Kompetenz-Prozess-Matrix'!D10) -> 0 | P8: =PRODUCT('Rollen-Prozess-Matrix'!T6,'Kompetenz-Prozess-Matrix'!D10) -> 2 | Q8: =PRODUCT('Rollen-Prozess-Matrix'!U6,'Kompetenz-Prozess-Matrix'!D10) -> 1
C9: 6.2.4 Personalwesen-Management | D9: =PRODUCT('Rollen-Prozess-Matrix'!H7,'Kompetenz-Prozess-Matrix'!D11) -> 0 | E9: =PRODUCT('Rollen-Prozess-Matrix'!I7,'Kompetenz-Prozess-Matrix'!D11) -> 0 | F9: =PRODUCT('Rollen-Prozess-Matrix'!J7,'Kompetenz-Prozess-Matrix'!D11) -> 0 | G9: =PRODUCT('Rollen-Prozess-Matrix'!K7,'Kompetenz-Prozess-Matrix'!D11) -> 2 | H9: =PRODUCT('Rollen-Prozess-Matrix'!L7,'Kompetenz-Prozess-Matrix'!D11) -> 3 | I9: =PRODUCT('Rollen-Prozess-Matrix'!M7,'Kompetenz-Prozess-Matrix'!D11) -> 0 | J9: =PRODUCT('Rollen-Prozess-Matrix'!N7,'Kompetenz-Prozess-Matrix'!D11) -> 0 | K9: =PRODUCT('Rollen-Prozess-Matrix'!O7,'Kompetenz-Prozess-Matrix'!D11) -> 0 | L9: =PRODUCT('Rollen-Prozess-Matrix'!P7,'Kompetenz-Prozess-Matrix'!D11) -> 0 | M9: =PRODUCT('Rollen-Prozess-Matrix'!Q7,'Kompetenz-Prozess-Matrix'!D11) -> 0 | N9: =PRODUCT('Rollen-Prozess-Matrix'!R7,'Kompetenz-Prozess-Matrix'!D11) -> 0 | O9: =PRODUCT('Rollen-Prozess-Matrix'!S7,'Kompetenz-Prozess-Matrix'!D11) -> 0 | P9: =PRODUCT('Rollen-Prozess-Matrix'!T7,'Kompetenz-Prozess-Matrix'!D11) -> 0 | Q9: =PRODUCT('Rollen-Prozess-Matrix'!U7,'Kompetenz-Prozess-Matrix'!D11) -> 1
C10: 6.2.5 Qualitätsmanagement | D10: =PRODUCT('Rollen-Prozess-Matrix'!H8,'Kompetenz-Prozess-Matrix'!D12) -> 0 | E10: =PRODUCT('Rollen-Prozess-Matrix'!I8,'Kompetenz-Prozess-Matrix'!D12) -> 0 | F10: =PRODUCT('Rollen-Prozess-Matrix'!J8,'Kompetenz-Prozess-Matrix'!D12) -> 0 | G10: =PRODUCT('Rollen-Prozess-Matrix'!K8,'Kompetenz-Prozess-Matrix'!D12) -> 0 | H10: =PRODUCT('Rollen-Prozess-Matrix'!L8,'Kompetenz-Prozess-Matrix'!D12) -> 3 | I10: =PRODUCT('Rollen-Prozess-Matrix'!M8,'Kompetenz-Prozess-Matrix'!D12) -> 0 | J10: =PRODUCT('Rollen-Prozess-Matrix'!N8,'Kompetenz-Prozess-Matrix'!D12) -> 0 | K10: =PRODUCT('Rollen-Prozess-Matrix'!O8,'Kompetenz-Prozess-Matrix'!D12) -> 0 | L10: =PRODUCT('Rollen-Prozess-Matrix'!P8,'Kompetenz-Prozess-Matrix'!D12) -> 1 | M10: =PRODUCT('Rollen-Prozess-Matrix'!Q8,'Kompetenz-Prozess-Matrix'!D12) -> 0 | N10: =PRODUCT('Rollen-Prozess-Matrix'!R8,'Kompetenz-Prozess-Matrix'!D12) -> 0 | O10: =PRODUCT('Rollen-Prozess-Matrix'!S8,'Kompetenz-Prozess-Matrix'!D12) -> 2 | P10: =PRODUCT('Rollen-Prozess-Matrix'!T8,'Kompetenz-Prozess-Matrix'!D12) -> 0 | Q10: =PRODUCT('Rollen-Prozess-Matrix'!U8,'Kompetenz-Prozess-Matrix'!D12) -> 0
C11: 6.2.6 Wissensmanagement | D11: =PRODUCT('Rollen-Prozess-Matrix'!H9,'Kompetenz-Prozess-Matrix'!D13) -> 0 | E11: =PRODUCT('Rollen-Prozess-Matrix'!I9,'Kompetenz-Prozess-Matrix'!D13) -> 0 | F11: =PRODUCT('Rollen-Prozess-Matrix'!J9,'Kompetenz-Prozess-Matrix'!D13) -> 0 | G11: =PRODUCT('Rollen-Prozess-Matrix'!K9,'Kompetenz-Prozess-Matrix'!D13) -> 2 | H11: =PRODUCT('Rollen-Prozess-Matrix'!L9,'Kompetenz-Prozess-Matrix'!D13) -> 3 | I11: =PRODUCT('Rollen-Prozess-Matrix'!M9,'Kompetenz-Prozess-Matrix'!D13) -> 0 | J11: =PRODUCT('Rollen-Prozess-Matrix'!N9,'Kompetenz-Prozess-Matrix'!D13) -> 0 | K11: =PRODUCT('Rollen-Prozess-Matrix'!O9,'Kompetenz-Prozess-Matrix'!D13) -> 0 | L11: =PRODUCT('Rollen-Prozess-Matrix'!P9,'Kompetenz-Prozess-Matrix'!D13) -> 0 | M11: =PRODUCT('Rollen-Prozess-Matrix'!Q9,'Kompetenz-Prozess-Matrix'!D13) -> 0 | N11: =PRODUCT('Rollen-Prozess-Matrix'!R9,'Kompetenz-Prozess-Matrix'!D13) -> 0 | O11: =PRODUCT('Rollen-Prozess-Matrix'!S9,'Kompetenz-Prozess-Matrix'!D13) -> 0 | P11: =PRODUCT('Rollen-Prozess-Matrix'!T9,'Kompetenz-Prozess-Matrix'!D13) -> 0 | Q11: =PRODUCT('Rollen-Prozess-Matrix'!U9,'Kompetenz-Prozess-Matrix'!D13) -> 0
C12: 6.3.1 Projektierung/Projektplanung | D12: =PRODUCT('Rollen-Prozess-Matrix'!H10,'Kompetenz-Prozess-Matrix'!D14) -> 0 | E12: =PRODUCT('Rollen-Prozess-Matrix'!I10,'Kompetenz-Prozess-Matrix'!D14) -> 0 | F12: =PRODUCT('Rollen-Prozess-Matrix'!J10,'Kompetenz-Prozess-Matrix'!D14) -> 4 | G12: =PRODUCT('Rollen-Prozess-Matrix'!K10,'Kompetenz-Prozess-Matrix'!D14) -> 0 | H12: =PRODUCT('Rollen-Prozess-Matrix'!L10,'Kompetenz-Prozess-Matrix'!D14) -> 6 | I12: =PRODUCT('Rollen-Prozess-Matrix'!M10,'Kompetenz-Prozess-Matrix'!D14) -> 0 | J12: =PRODUCT('Rollen-Prozess-Matrix'!N10,'Kompetenz-Prozess-Matrix'!D14) -> 0 | K12: =PRODUCT('Rollen-Prozess-Matrix'!O10,'Kompetenz-Prozess-Matrix'!D14) -> 0 | L12: =PRODUCT('Rollen-Prozess-Matrix'!P10,'Kompetenz-Prozess-Matrix'!D14) -> 0 | M12: =PRODUCT('Rollen-Prozess-Matrix'!Q10,'Kompetenz-Prozess-Matrix'!D14) -> 0 | N12: =PRODUCT('Rollen-Prozess-Matrix'!R10,'Kompetenz-Prozess-Matrix'!D14) -> 0 | O12: =PRODUCT('Rollen-Prozess-Matrix'!S10,'Kompetenz-Prozess-Matrix'!D14) -> 0 | P12: =PRODUCT('Rollen-Prozess-Matrix'!T10,'Kompetenz-Prozess-Matrix'!D14) -> 0 | Q12: =PRODUCT('Rollen-Prozess-Matrix'!U10,'Kompetenz-Prozess-Matrix'!D14) -> 0
C13: 6.3.2 Projektbewertung und Steuerung | D13: =PRODUCT('Rollen-Prozess-Matrix'!H11,'Kompetenz-Prozess-Matrix'!D15) -> 0 | E13: =PRODUCT('Rollen-Prozess-Matrix'!I11,'Kompetenz-Prozess-Matrix'!D15) -> 0 | F13: =PRODUCT('Rollen-Prozess-Matrix'!J11,'Kompetenz-Prozess-Matrix'!D15) -> 2 | G13: =PRODUCT('Rollen-Prozess-Matrix'!K11,'Kompetenz-Prozess-Matrix'!D15) -> 0 | H13: =PRODUCT('Rollen-Prozess-Matrix'!L11,'Kompetenz-Prozess-Matrix'!D15) -> 3 | I13: =PRODUCT('Rollen-Prozess-Matrix'!M11,'Kompetenz-Prozess-Matrix'!D15) -> 0 | J13: =PRODUCT('Rollen-Prozess-Matrix'!N11,'Kompetenz-Prozess-Matrix'!D15) -> 0 | K13: =PRODUCT('Rollen-Prozess-Matrix'!O11,'Kompetenz-Prozess-Matrix'!D15) -> 0 | L13: =PRODUCT('Rollen-Prozess-Matrix'!P11,'Kompetenz-Prozess-Matrix'!D15) -> 0 | M13: =PRODUCT('Rollen-Prozess-Matrix'!Q11,'Kompetenz-Prozess-Matrix'!D15) -> 0 | N13: =PRODUCT('Rollen-Prozess-Matrix'!R11,'Kompetenz-Prozess-Matrix'!D15) -> 0 | O13: =PRODUCT('Rollen-Prozess-Matrix'!S11,'Kompetenz-Prozess-Matrix'!D15) -> 0 | P13: =PRODUCT('Rollen-Prozess-Matrix'!T11,'Kompetenz-Prozess-Matrix'!D15) -> 0 | Q13: =PRODUCT('Rollen-Prozess-Matrix'!U11,'Kompetenz-Prozess-Matrix'!D15) -> 1
C14: 6.3.3 Entscheidungsmanagement | D14: =PRODUCT('Rollen-Prozess-Matrix'!H12,'Kompetenz-Prozess-Matrix'!D16) -> 0 | E14: =PRODUCT('Rollen-Prozess-Matrix'!I12,'Kompetenz-Prozess-Matrix'!D16) -> 2 | F14: =PRODUCT('Rollen-Prozess-Matrix'!J12,'Kompetenz-Prozess-Matrix'!D16) -> 2 | G14: =PRODUCT('Rollen-Prozess-Matrix'!K12,'Kompetenz-Prozess-Matrix'!D16) -> 0 | H14: =PRODUCT('Rollen-Prozess-Matrix'!L12,'Kompetenz-Prozess-Matrix'!D16) -> 3 | I14: =PRODUCT('Rollen-Prozess-Matrix'!M12,'Kompetenz-Prozess-Matrix'!D16) -> 2 | J14: =PRODUCT('Rollen-Prozess-Matrix'!N12,'Kompetenz-Prozess-Matrix'!D16) -> 1 | K14: =PRODUCT('Rollen-Prozess-Matrix'!O12,'Kompetenz-Prozess-Matrix'!D16) -> 1 | L14: =PRODUCT('Rollen-Prozess-Matrix'!P12,'Kompetenz-Prozess-Matrix'!D16) -> 1 | M14: =PRODUCT('Rollen-Prozess-Matrix'!Q12,'Kompetenz-Prozess-Matrix'!D16) -> 0 | N14: =PRODUCT('Rollen-Prozess-Matrix'!R12,'Kompetenz-Prozess-Matrix'!D16) -> 0 | O14: =PRODUCT('Rollen-Prozess-Matrix'!S12,'Kompetenz-Prozess-Matrix'!D16) -> 0 | P14: =PRODUCT('Rollen-Prozess-Matrix'!T12,'Kompetenz-Prozess-Matrix'!D16) -> 1 | Q14: =PRODUCT('Rollen-Prozess-Matrix'!U12,'Kompetenz-Prozess-Matrix'!D16) -> 2
C15: 6.3.4 Risiko-Management | D15: =PRODUCT('Rollen-Prozess-Matrix'!H13,'Kompetenz-Prozess-Matrix'!D17) -> 0 | E15: =PRODUCT('Rollen-Prozess-Matrix'!I13,'Kompetenz-Prozess-Matrix'!D17) -> 1 | F15: =PRODUCT('Rollen-Prozess-Matrix'!J13,'Kompetenz-Prozess-Matrix'!D17) -> 2 | G15: =PRODUCT('Rollen-Prozess-Matrix'!K13,'Kompetenz-Prozess-Matrix'!D17) -> 0 | H15: =PRODUCT('Rollen-Prozess-Matrix'!L13,'Kompetenz-Prozess-Matrix'!D17) -> 3 | I15: =PRODUCT('Rollen-Prozess-Matrix'!M13,'Kompetenz-Prozess-Matrix'!D17) -> 2 | J15: =PRODUCT('Rollen-Prozess-Matrix'!N13,'Kompetenz-Prozess-Matrix'!D17) -> 1 | K15: =PRODUCT('Rollen-Prozess-Matrix'!O13,'Kompetenz-Prozess-Matrix'!D17) -> 1 | L15: =PRODUCT('Rollen-Prozess-Matrix'!P13,'Kompetenz-Prozess-Matrix'!D17) -> 0 | M15: =PRODUCT('Rollen-Prozess-Matrix'!Q13,'Kompetenz-Prozess-Matrix'!D17) -> 0 | N15: =PRODUCT('Rollen-Prozess-Matrix'!R13,'Kompetenz-Prozess-Matrix'!D17) -> 0 | O15: =PRODUCT('Rollen-Prozess-Matrix'!S13,'Kompetenz-Prozess-Matrix'!D17) -> 1 | P15: =PRODUCT('Rollen-Prozess-Matrix'!T13,'Kompetenz-Prozess-Matrix'!D17) -> 0 | Q15: =PRODUCT('Rollen-Prozess-Matrix'!U13,'Kompetenz-Prozess-Matrix'!D17) -> 0
... C36: Qualifizierung | D36: =PRODUCT('Rollen-Prozess-Matrix'!H34,'Kompetenz-Prozess-Matrix'!D38) -> 0 | E36: =PRODUCT('Rollen-Prozess-Matrix'!I34,'Kompetenz-Prozess-Matrix'!D38) -> 0 | F36: =PRODUCT('Rollen-Prozess-Matrix'!J34,'Kompetenz-Prozess-Matrix'!D38) -> 0 | G36: =PRODUCT('Rollen-Prozess-Matrix'!K34,'Kompetenz-Prozess-Matrix'!D38) -> 4 | H36: =PRODUCT('Rollen-Prozess-Matrix'!L34,'Kompetenz-Prozess-Matrix'!D38) -> 0 | I36: =PRODUCT('Rollen-Prozess-Matrix'!M34,'Kompetenz-Prozess-Matrix'!D38) -> 0 | J36: =PRODUCT('Rollen-Prozess-Matrix'!N34,'Kompetenz-Prozess-Matrix'!D38) -> 0 | K36: =PRODUCT('Rollen-Prozess-Matrix'!O34,'Kompetenz-Prozess-Matrix'!D38) -> 0 | L36: =PRODUCT('Rollen-Prozess-Matrix'!P34,'Kompetenz-Prozess-Matrix'!D38) -> 0 | M36: =PRODUCT('Rollen-Prozess-Matrix'!Q34,'Kompetenz-Prozess-Matrix'!D38) -> 0 | N36: =PRODUCT('Rollen-Prozess-Matrix'!R34,'Kompetenz-Prozess-Matrix'!D38) -> 0 | O36: =PRODUCT('Rollen-Prozess-Matrix'!S34,'Kompetenz-Prozess-Matrix'!D38) -> 0 | P36: =PRODUCT('Rollen-Prozess-Matrix'!T34,'Kompetenz-Prozess-Matrix'!D38) -> 0 | Q36: =PRODUCT('Rollen-Prozess-Matrix'!U34,'Kompetenz-Prozess-Matrix'!D38) -> 0
B37: Systemmodellierung und -analyse | D37: =MAX(D38:D70) -> 2 | E37: =MAX(E38:E70) -> 4 | F37: =MAX(F38:F70) -> 4 | G37: =MAX(G38:G70) -> 4 | H37: =MAX(H38:H70) -> 6 | I37: =MAX(I38:I70) -> 4 | J37: =MAX(J38:J70) -> 4 | K37: =MAX(K38:K70) -> 2 | ... Q37: =MAX(Q38:Q70) -> 2 | S37: 1
C38: 6.1.1 Akquisition | D38: =PRODUCT('Rollen-Prozess-Matrix'!H2,'Kompetenz-Prozess-Matrix'!E6) -> 0 | E38: =PRODUCT('Rollen-Prozess-Matrix'!I2,'Kompetenz-Prozess-Matrix'!E6) -> 0 | F38: =PRODUCT('Rollen-Prozess-Matrix'!J2,'Kompetenz-Prozess-Matrix'!E6) -> 0 | G38: =PRODUCT('Rollen-Prozess-Matrix'!K2,'Kompetenz-Prozess-Matrix'!E6) -> 0 | H38: =PRODUCT('Rollen-Prozess-Matrix'!L2,'Kompetenz-Prozess-Matrix'!E6) -> 0 | I38: =PRODUCT('Rollen-Prozess-Matrix'!M2,'Kompetenz-Prozess-Matrix'!E6) -> 0 | J38: =PRODUCT('Rollen-Prozess-Matrix'!N2,'Kompetenz-Prozess-Matrix'!E6) -> 0 | K38: =PRODUCT('Rollen-Prozess-Matrix'!O2,'Kompetenz-Prozess-Matrix'!E6) -> 0 | L38: =PRODUCT('Rollen-Prozess-Matrix'!P2,'Kompetenz-Prozess-Matrix'!E6) -> 0 | M38: =PRODUCT('Rollen-Prozess-Matrix'!Q2,'Kompetenz-Prozess-Matrix'!E6) -> 0 | N38: =PRODUCT('Rollen-Prozess-Matrix'!R2,'Kompetenz-Prozess-Matrix'!E6) -> 0 | O38: =PRODUCT('Rollen-Prozess-Matrix'!S2,'Kompetenz-Prozess-Matrix'!E6) -> 0 | P38: =PRODUCT('Rollen-Prozess-Matrix'!T2,'Kompetenz-Prozess-Matrix'!E6) -> 0 | Q38: =PRODUCT('Rollen-Prozess-Matrix'!U2,'Kompetenz-Prozess-Matrix'!E6) -> 0
C39: 6.1.2 Lieferung | D39: =PRODUCT('Rollen-Prozess-Matrix'!H3,'Kompetenz-Prozess-Matrix'!E7) -> 0 | E39: =PRODUCT('Rollen-Prozess-Matrix'!I3,'Kompetenz-Prozess-Matrix'!E7) -> 0 | F39: =PRODUCT('Rollen-Prozess-Matrix'!J3,'Kompetenz-Prozess-Matrix'!E7) -> 0 | G39: =PRODUCT('Rollen-Prozess-Matrix'!K3,'Kompetenz-Prozess-Matrix'!E7) -> 0 | H39: =PRODUCT('Rollen-Prozess-Matrix'!L3,'Kompetenz-Prozess-Matrix'!E7) -> 0 | I39: =PRODUCT('Rollen-Prozess-Matrix'!M3,'Kompetenz-Prozess-Matrix'!E7) -> 0 | J39: =PRODUCT('Rollen-Prozess-Matrix'!N3,'Kompetenz-Prozess-Matrix'!E7) -> 0 | K39: =PRODUCT('Rollen-Prozess-Matrix'!O3,'Kompetenz-Prozess-Matrix'!E7) -> 0 | L39: =PRODUCT('Rollen-Prozess-Matrix'!P3,'Kompetenz-Prozess-Matrix'!E7) -> 0 | M39: =PRODUCT('Rollen-Prozess-Matrix'!Q3,'Kompetenz-Prozess-Matrix'!E7) -> 0 | N39: =PRODUCT('Rollen-Prozess-Matrix'!R3,'Kompetenz-Prozess-Matrix'!E7) -> 0 | O39: =PRODUCT('Rollen-Prozess-Matrix'!S3,'Kompetenz-Prozess-Matrix'!E7) -> 0 | P39: =PRODUCT('Rollen-Prozess-Matrix'!T3,'Kompetenz-Prozess-Matrix'!E7) -> 0 | Q39: =PRODUCT('Rollen-Prozess-Matrix'!U3,'Kompetenz-Prozess-Matrix'!E7) -> 0
C40: 6.2.1 Lebenszyklus-Modell-Management | D40: =PRODUCT('Rollen-Prozess-Matrix'!H4,'Kompetenz-Prozess-Matrix'!E8) -> 0 | E40: =PRODUCT('Rollen-Prozess-Matrix'!I4,'Kompetenz-Prozess-Matrix'!E8) -> 0 | F40: =PRODUCT('Rollen-Prozess-Matrix'!J4,'Kompetenz-Prozess-Matrix'!E8) -> 0 | G40: =PRODUCT('Rollen-Prozess-Matrix'!K4,'Kompetenz-Prozess-Matrix'!E8) -> 2 | H40: =PRODUCT('Rollen-Prozess-Matrix'!L4,'Kompetenz-Prozess-Matrix'!E8) -> 6 | I40: =PRODUCT('Rollen-Prozess-Matrix'!M4,'Kompetenz-Prozess-Matrix'!E8) -> 0 | J40: =PRODUCT('Rollen-Prozess-Matrix'!N4,'Kompetenz-Prozess-Matrix'!E8) -> 0 | K40: =PRODUCT('Rollen-Prozess-Matrix'!O4,'Kompetenz-Prozess-Matrix'!E8) -> 0 | L40: =PRODUCT('Rollen-Prozess-Matrix'!P4,'Kompetenz-Prozess-Matrix'!E8) -> 0 | M40: =PRODUCT('Rollen-Prozess-Matrix'!Q4,'Kompetenz-Prozess-Matrix'!E8) -> 0 | N40: =PRODUCT('Rollen-Prozess-Matrix'!R4,'Kompetenz-Prozess-Matrix'!E8) -> 0 | O40: =PRODUCT('Rollen-Prozess-Matrix'!S4,'Kompetenz-Prozess-Matrix'!E8) -> 0 | P40: =PRODUCT('Rollen-Prozess-Matrix'!T4,'Kompetenz-Prozess-Matrix'!E8) -> 0 | Q40: =PRODUCT('Rollen-Prozess-Matrix'!U4,'Kompetenz-Prozess-Matrix'!E8) -> 0
C41: 6.2.2 Verwaltung der Infrastruktur | D41: =PRODUCT('Rollen-Prozess-Matrix'!H5,'Kompetenz-Prozess-Matrix'!E9) -> 0 | E41: =PRODUCT('Rollen-Prozess-Matrix'!I5,'Kompetenz-Prozess-Matrix'!E9) -> 0 | F41: =PRODUCT('Rollen-Prozess-Matrix'!J5,'Kompetenz-Prozess-Matrix'!E9) -> 0 | G41: =PRODUCT('Rollen-Prozess-Matrix'!K5,'Kompetenz-Prozess-Matrix'!E9) -> 2 | H41: =PRODUCT('Rollen-Prozess-Matrix'!L5,'Kompetenz-Prozess-Matrix'!E9) -> 3 | I41: =PRODUCT('Rollen-Prozess-Matrix'!M5,'Kompetenz-Prozess-Matrix'!E9) -> 0 | J41: =PRODUCT('Rollen-Prozess-Matrix'!N5,'Kompetenz-Prozess-Matrix'!E9) -> 0 | K41: =PRODUCT('Rollen-Prozess-Matrix'!O5,'Kompetenz-Prozess-Matrix'!E9) -> 0 | L41: =PRODUCT('Rollen-Prozess-Matrix'!P5,'Kompetenz-Prozess-Matrix'!E9) -> 0 | M41: =PRODUCT('Rollen-Prozess-Matrix'!Q5,'Kompetenz-Prozess-Matrix'!E9) -> 0 | N41: =PRODUCT('Rollen-Prozess-Matrix'!R5,'Kompetenz-Prozess-Matrix'!E9) -> 0 | O41: =PRODUCT('Rollen-Prozess-Matrix'!S5,'Kompetenz-Prozess-Matrix'!E9) -> 0 | P41: =PRODUCT('Rollen-Prozess-Matrix'!T5,'Kompetenz-Prozess-Matrix'!E9) -> 0 | Q41: =PRODUCT('Rollen-Prozess-Matrix'!U5,'Kompetenz-Prozess-Matrix'!E9) -> 0
C42: 6.2.3 Portfoliomanagement | D42: =PRODUCT('Rollen-Prozess-Matrix'!H6,'Kompetenz-Prozess-Matrix'!E10) -> 0 | E42: =PRODUCT('Rollen-Prozess-Matrix'!I6,'Kompetenz-Prozess-Matrix'!E10) -> 0 | F42: =PRODUCT('Rollen-Prozess-Matrix'!J6,'Kompetenz-Prozess-Matrix'!E10) -> 0 | G42: =PRODUCT('Rollen-Prozess-Matrix'!K6,'Kompetenz-Prozess-Matrix'!E10) -> 0 | H42: =PRODUCT('Rollen-Prozess-Matrix'!L6,'Kompetenz-Prozess-Matrix'!E10) -> 0 | I42: =PRODUCT('Rollen-Prozess-Matrix'!M6,'Kompetenz-Prozess-Matrix'!E10) -> 0 | J42: =PRODUCT('Rollen-Prozess-Matrix'!N6,'Kompetenz-Prozess-Matrix'!E10) -> 0 | K42: =PRODUCT('Rollen-Prozess-Matrix'!O6,'Kompetenz-Prozess-Matrix'!E10) -> 0 | L42: =PRODUCT('Rollen-Prozess-Matrix'!P6,'Kompetenz-Prozess-Matrix'!E10) -> 0 | M42: =PRODUCT('Rollen-Prozess-Matrix'!Q6,'Kompetenz-Prozess-Matrix'!E10) -> 0 | N42: =PRODUCT('Rollen-Prozess-Matrix'!R6,'Kompetenz-Prozess-Matrix'!E10) -> 0 | O42: =PRODUCT('Rollen-Prozess-Matrix'!S6,'Kompetenz-Prozess-Matrix'!E10) -> 0 | P42: =PRODUCT('Rollen-Prozess-Matrix'!T6,'Kompetenz-Prozess-Matrix'!E10) -> 0 | Q42: =PRODUCT('Rollen-Prozess-Matrix'!U6,'Kompetenz-Prozess-Matrix'!E10) -> 0
C43: 6.2.4 Personalwesen-Management | D43: =PRODUCT('Rollen-Prozess-Matrix'!H7,'Kompetenz-Prozess-Matrix'!E11) -> 0 | E43: =PRODUCT('Rollen-Prozess-Matrix'!I7,'Kompetenz-Prozess-Matrix'!E11) -> 0 | F43: =PRODUCT('Rollen-Prozess-Matrix'!J7,'Kompetenz-Prozess-Matrix'!E11) -> 0 | G43: =PRODUCT('Rollen-Prozess-Matrix'!K7,'Kompetenz-Prozess-Matrix'!E11) -> 2 | H43: =PRODUCT('Rollen-Prozess-Matrix'!L7,'Kompetenz-Prozess-Matrix'!E11) -> 3 | I43: =PRODUCT('Rollen-Prozess-Matrix'!M7,'Kompetenz-Prozess-Matrix'!E11) -> 0 | J43: =PRODUCT('Rollen-Prozess-Matrix'!N7,'Kompetenz-Prozess-Matrix'!E11) -> 0 | K43: =PRODUCT('Rollen-Prozess-Matrix'!O7,'Kompetenz-Prozess-Matrix'!E11) -> 0 | L43: =PRODUCT('Rollen-Prozess-Matrix'!P7,'Kompetenz-Prozess-Matrix'!E11) -> 0 | M43: =PRODUCT('Rollen-Prozess-Matrix'!Q7,'Kompetenz-Prozess-Matrix'!E11) -> 0 | N43: =PRODUCT('Rollen-Prozess-Matrix'!R7,'Kompetenz-Prozess-Matrix'!E11) -> 0 | O43: =PRODUCT('Rollen-Prozess-Matrix'!S7,'Kompetenz-Prozess-Matrix'!E11) -> 0 | P43: =PRODUCT('Rollen-Prozess-Matrix'!T7,'Kompetenz-Prozess-Matrix'!E11) -> 0 | Q43: =PRODUCT('Rollen-Prozess-Matrix'!U7,'Kompetenz-Prozess-Matrix'!E11) -> 1
C44: 6.2.5 Qualitätsmanagement | D44: =PRODUCT('Rollen-Prozess-Matrix'!H8,'Kompetenz-Prozess-Matrix'!E12) -> 0 | E44: =PRODUCT('Rollen-Prozess-Matrix'!I8,'Kompetenz-Prozess-Matrix'!E12) -> 0 | F44: =PRODUCT('Rollen-Prozess-Matrix'!J8,'Kompetenz-Prozess-Matrix'!E12) -> 0 | G44: =PRODUCT('Rollen-Prozess-Matrix'!K8,'Kompetenz-Prozess-Matrix'!E12) -> 0 | H44: =PRODUCT('Rollen-Prozess-Matrix'!L8,'Kompetenz-Prozess-Matrix'!E12) -> 3 | I44: =PRODUCT('Rollen-Prozess-Matrix'!M8,'Kompetenz-Prozess-Matrix'!E12) -> 0 | J44: =PRODUCT('Rollen-Prozess-Matrix'!N8,'Kompetenz-Prozess-Matrix'!E12) -> 0 | K44: =PRODUCT('Rollen-Prozess-Matrix'!O8,'Kompetenz-Prozess-Matrix'!E12) -> 0 | L44: =PRODUCT('Rollen-Prozess-Matrix'!P8,'Kompetenz-Prozess-Matrix'!E12) -> 1 | M44: =PRODUCT('Rollen-Prozess-Matrix'!Q8,'Kompetenz-Prozess-Matrix'!E12) -> 0 | N44: =PRODUCT('Rollen-Prozess-Matrix'!R8,'Kompetenz-Prozess-Matrix'!E12) -> 0 | O44: =PRODUCT('Rollen-Prozess-Matrix'!S8,'Kompetenz-Prozess-Matrix'!E12) -> 2 | P44: =PRODUCT('Rollen-Prozess-Matrix'!T8,'Kompetenz-Prozess-Matrix'!E12) -> 0 | Q44: =PRODUCT('Rollen-Prozess-Matrix'!U8,'Kompetenz-Prozess-Matrix'!E12) -> 0
C45: 6.2.6 Wissensmanagement | D45: =PRODUCT('Rollen-Prozess-Matrix'!H9,'Kompetenz-Prozess-Matrix'!E13) -> 0 | E45: =PRODUCT('Rollen-Prozess-Matrix'!I9,'Kompetenz-Prozess-Matrix'!E13) -> 0 | F45: =PRODUCT('Rollen-Prozess-Matrix'!J9,'Kompetenz-Prozess-Matrix'!E13) -> 0 | G45: =PRODUCT('Rollen-Prozess-Matrix'!K9,'Kompetenz-Prozess-Matrix'!E13) -> 2 | H45: =PRODUCT('Rollen-Prozess-Matrix'!L9,'Kompetenz-Prozess-Matrix'!E13) -> 3 | I45: =PRODUCT('Rollen-Prozess-Matrix'!M9,'Kompetenz-Prozess-Matrix'!E13) -> 0 | J45: =PRODUCT('Rollen-Prozess-Matrix'!N9,'Kompetenz-Prozess-Matrix'!E13) -> 0 | K45: =PRODUCT('Rollen-Prozess-Matrix'!O9,'Kompetenz-Prozess-Matrix'!E13) -> 0 | L45: =PRODUCT('Rollen-Prozess-Matrix'!P9,'Kompetenz-Prozess-Matrix'!E13) -> 0 | M45: =PRODUCT('Rollen-Prozess-Matrix'!Q9,'Kompetenz-Prozess-Matrix'!E13) -> 0 | N45: =PRODUCT('Rollen-Prozess-Matrix'!R9,'Kompetenz-Prozess-Matrix'!E13) -> 0 | O45: =PRODUCT('Rollen-Prozess-Matrix'!S9,'Kompetenz-Prozess-Matrix'!E13) -> 0 | P45: =PRODUCT('Rollen-Prozess-Matrix'!T9,'Kompetenz-Prozess-Matrix'!E13) -> 0 | Q45: =PRODUCT('Rollen-Prozess-Matrix'!U9,'Kompetenz-Prozess-Matrix'!E13) -> 0
C46: 6.3.1 Projektierung/Projektplanung | D46: =PRODUCT('Rollen-Prozess-Matrix'!H10,'Kompetenz-Prozess-Matrix'!E14) -> 0 | E46: =PRODUCT('Rollen-Prozess-Matrix'!I10,'Kompetenz-Prozess-Matrix'!E14) -> 0 | F46: =PRODUCT('Rollen-Prozess-Matrix'!J10,'Kompetenz-Prozess-Matrix'!E14) -> 0 | G46: =PRODUCT('Rollen-Prozess-Matrix'!K10,'Kompetenz-Prozess-Matrix'!E14) -> 0 | H46: =PRODUCT('Rollen-Prozess-Matrix'!L10,'Kompetenz-Prozess-Matrix'!E14) -> 0 | I46: =PRODUCT('Rollen-Prozess-Matrix'!M10,'Kompetenz-Prozess-Matrix'!E14) -> 0 | J46: =PRODUCT('Rollen-Prozess-Matrix'!N10,'Kompetenz-Prozess-Matrix'!E14) -> 0 | K46: =PRODUCT('Rollen-Prozess-Matrix'!O10,'Kompetenz-Prozess-Matrix'!E14) -> 0 | L46: =PRODUCT('Rollen-Prozess-Matrix'!P10,'Kompetenz-Prozess-Matrix'!E14) -> 0 | M46: =PRODUCT('Rollen-Prozess-Matrix'!Q10,'Kompetenz-Prozess-Matrix'!E14) -> 0 | N46: =PRODUCT('Rollen-Prozess-Matrix'!R10,'Kompetenz-Prozess-Matrix'!E14) -> 0 | O46: =PRODUCT('Rollen-Prozess-Matrix'!S10,'Kompetenz-Prozess-Matrix'!E14) -> 0 | P46: =PRODUCT('Rollen-Prozess-Matrix'!T10,'Kompetenz-Prozess-Matrix'!E14) -> 0 | Q46: =PRODUCT('Rollen-Prozess-Matrix'!U10,'Kompetenz-Prozess-Matrix'!E14) -> 0
C47: 6.3.2 Projektbewertung und Steuerung | D47: =PRODUCT('Rollen-Prozess-Matrix'!H11,'Kompetenz-Prozess-Matrix'!E15) -> 0 | E47: =PRODUCT('Rollen-Prozess-Matrix'!I11,'Kompetenz-Prozess-Matrix'!E15) -> 0 | F47: =PRODUCT('Rollen-Prozess-Matrix'!J11,'Kompetenz-Prozess-Matrix'!E15) -> 0 | G47: =PRODUCT('Rollen-Prozess-Matrix'!K11,'Kompetenz-Prozess-Matrix'!E15) -> 0 | H47: =PRODUCT('Rollen-Prozess-Matrix'!L11,'Kompetenz-Prozess-Matrix'!E15) -> 0 | I47: =PRODUCT('Rollen-Prozess-Matrix'!M11,'Kompetenz-Prozess-Matrix'!E15) -> 0 | J47: =PRODUCT('Rollen-Prozess-Matrix'!N11,'Kompetenz-Prozess-Matrix'!E15) -> 0 | K47: =PRODUCT('Rollen-Prozess-Matrix'!O11,'Kompetenz-Prozess-Matrix'!E15) -> 0 | L47: =PRODUCT('Rollen-Prozess-Matrix'!P11,'Kompetenz-Prozess-Matrix'!E15) -> 0 | M47: =PRODUCT('Rollen-Prozess-Matrix'!Q11,'Kompetenz-Prozess-Matrix'!E15) -> 0 | N47: =PRODUCT('Rollen-Prozess-Matrix'!R11,'Kompetenz-Prozess-Matrix'!E15) -> 0 | O47: =PRODUCT('Rollen-Prozess-Matrix'!S11,'Kompetenz-Prozess-Matrix'!E15) -> 0 | P47: =PRODUCT('Rollen-Prozess-Matrix'!T11,'Kompetenz-Prozess-Matrix'!E15) -> 0 | Q47: =PRODUCT('Rollen-Prozess-Matrix'!U11,'Kompetenz-Prozess-Matrix'!E15) -> 0
